Workbook
Name Accounts_IDList: OFFSET(#REF!,0,0,COUNTA(#REF!)-1,1)
Name Accounts_NameList: OFFSET(#REF!,0,0,COUNTA(#REF!)-1,1)
Name BainPoC_FullNames: OFFSET(Bain_POCs!$A$2,0,0,COUNTA(Bain_POCs!$A:$A)-1,1)
Name IQ_CH: 110000
Name IQ_CQ: 5000
Name IQ_CY: 10000
Name IQ_DAILY: 500000
Name IQ_FH: 100000
Name IQ_FQ: 500
Name IQ_FY: 1000
Name IQ_LTM: 2000
Name IQ_MONTH: 15000
Name IQ_NTM: 6000
Name IQ_WEEK: 50000
Name IQ_YTD: 3000

Sheet Index
A1: CRM Input Database — Index
A2: Click a sheet name below to jump to it.
A4: Sheet | B4: Purpose
A5: Input Contact Information | B5: The only sheet you need to maintain. Enter each partner, company, and contact's details here — every other sheet updates from this automatically.
A6: Accounts Overview | B6: One row per client account: company profile (sector, website, competitors, HQ) plus a live engagement health summary.
A7: Contacts Overview | B7: One row per contact: profile details combined with tier, target cadence, and current engagement status.
A8: Engagements Overview | B8: Tracks each contact's last engagement date and follow-up status, calculated against the cadence rules in Methodology.
A9: Bain_POCs | B9: Reference list of Bain partners and points of contact — powers the dropdown lists used throughout the workbook.
A10: Methodology | B10: Reference rules for how Contact Tier, Target Cadence, and Engagement Status are calculated.
A12: Tip: sheet names above are clickable links. From any other sheet, right-click the sheet-navigation arrows in the bottom-left corner of Excel to jump straight back here.

Sheet Input sheet>>

Sheet Input Contact Information
A1: Partner Name | B1: Company Name | C1: Contact Person Full Name | D1: Designation | E1: Mobile/ Whatsapp number | F1: Email | G1: Linkedin/ public profile URL | H1: Base city/ location | I1: Preferred channel of outreach | J1: Seniority | K1: Relationship Quality | L1: Account Revenue | M1: Automatic tier assigned | N1: Manual Tier change? | O1: Professional interests Interests | P1: Personal Interests | Q1: Last engagement date | R1: Next steps | S1: Company - First Occurrence? (helper) | T1: Company - Unique Rank (helper) | U1: Contact - First Occurrence? (helper, keyed on Name+Company) | V1: Contact - Unique Rank (helper, keyed on Name+Company) | W1: Contact+Company composite key (helper)
A2: Wael Hatoum | B2: QatarEnergy | C2: Amal Al Noor | D2: Chief Executive Officer | F2: amal.alnoor@sample-1.example | I2: Email | J2: High | K2: High | L2: High | M2: =IF(OR(J2="",K2="",L2=""),"",IF(AND(COUNTIF(J2:L2,"High")>=2,OR(J2="High",L2="High")),"Tier 1",IF(AND(COUNTIF(J2:L2,"High")>=1,COUNTIF(J2:L2,"Medium")>=1),"Tier 2","Tier 3"))) -> Tier 1 | O2: Energy transition — interested in decarbonisation pathways and global demand shifts; LNG — interested in the strategic role of LNG in the energy transition. | P2: Golf — follows major golf events; Travel — enjoys distinctive destinations, resorts and courses. | Q2: 46219 | S2: =IF(B2="",0,IF(COUNTIF($B$2:$B2,B2)=1,1,0)) -> 1 | T2: =IF(S2=1,SUM($S$2:S2),"") -> 1 | U2: =IF(W2="",0,IF(COUNTIF($W$2:$W2,W2)=1,1,0)) -> 1 | V2: =IF(U2=1,SUM($U$2:U2),"") -> 1 | W2: =IF(OR(C2="",B2=""),"",TRIM(C2)&"|"&TRIM(B2)) -> Amal Al Noor|QatarEnergy
A3: Wael Hatoum | B3: QatarEnergy | C3: Khalid Al Thani | D3: Chief Strategy Officer | F3: khalid.althani@sample-1.example | I3: Email | J3: High | K3: Medium | L3: High | M3: =IF(OR(J3="",K3="",L3=""),"",IF(AND(COUNTIF(J3:L3,"High")>=2,OR(J3="High",L3="High")),"Tier 1",IF(AND(COUNTIF(J3:L3,"High")>=1,COUNTIF(J3:L3,"Medium")>=1),"Tier 2","Tier 3"))) -> Tier 1 | O3: Corporate strategy — interested in portfolio choices and how energy companies create value across assets; Energy trading — follows market volatility and trading opportunities. | P3: Reading — enjoys business and current-affairs books; Padel — follows or plays padel socially. | Q3: 46184 | S3: =IF(B3="",0,IF(COUNTIF($B$2:$B3,B3)=1,1,0)) -> 0 | T3: =IF(S3=1,SUM($S$2:S3),"") | U3: =IF(W3="",0,IF(COUNTIF($W$2:$W3,W3)=1,1,0)) -> 1 | V3: =IF(U3=1,SUM($U$2:U3),"") -> 2 | W3: =IF(OR(C3="",B3=""),"",TRIM(C3)&"|"&TRIM(B3)) -> Khalid Al Thani|QatarEnergy
A4: Wael Hatoum | B4: QatarEnergy | C4: Mariam Al Suwaidi | D4: Vice President, Strategy | F4: mariam.alsuwaidi@sample-1.example | I4: Email | J4: High | K4: Medium | L4: High | M4: =IF(OR(J4="",K4="",L4=""),"",IF(AND(COUNTIF(J4:L4,"High")>=2,OR(J4="High",L4="High")),"Tier 1",IF(AND(COUNTIF(J4:L4,"High")>=1,COUNTIF(J4:L4,"Medium")>=1),"Tier 2","Tier 3"))) -> Tier 1 | O4: Decarbonisation — interested in scalable emissions reduction; Capital projects — interested in project economics and delivery of large energy investments. | P4: Photography — enjoys destination and architectural photography; Travel — interested in culturally or visually distinctive places. | Q4: 46154 | S4: =IF(B4="",0,IF(COUNTIF($B$2:$B4,B4)=1,1,0)) -> 0 | T4: =IF(S4=1,SUM($S$2:S4),"") | U4: =IF(W4="",0,IF(COUNTIF($W$2:$W4,W4)=1,1,0)) -> 1 | V4: =IF(U4=1,SUM($U$2:U4),"") -> 3 | W4: =IF(OR(C4="",B4=""),"",TRIM(C4)&"|"&TRIM(B4)) -> Mariam Al Suwaidi|QatarEnergy
A5: Alberto Michelotti | B5: Qatar Airways Group | C5: Fahad Al Kuwari | D5: Chief Executive Officer | F5: fahad.alkuwari@sample-2.example | I5: Email | J5: High | K5: Medium | L5: High | M5: =IF(OR(J5="",K5="",L5=""),"",IF(AND(COUNTIF(J5:L5,"High")>=2,OR(J5="High",L5="High")),"Tier 1",IF(AND(COUNTIF(J5:L5,"High")>=1,COUNTIF(J5:L5,"Medium")>=1),"Tier 2","Tier 3"))) -> Tier 1 | O5: Airline strategy — interested in network economics, growth and profitability; Fleet expansion — interested in fleet choices and how they support network growth and customer experience. | P5: Football — follows major football competitions; Aviation history — enjoys stories about iconic aircraft, airlines and aviation milestones. | Q5: 46219 | S5: =IF(B5="",0,IF(COUNTIF($B$2:$B5,B5)=1,1,0)) -> 1 | T5: =IF(S5=1,SUM($S$2:S5),"") -> 2 | U5: =IF(W5="",0,IF(COUNTIF($W$2:$W5,W5)=1,1,0)) -> 1 | V5: =IF(U5=1,SUM($U$2:U5),"") -> 4 | W5: =IF(OR(C5="",B5=""),"",TRIM(C5)&"|"&TRIM(B5)) -> Fahad Al Kuwari|Qatar Airways Group
A6: Alberto Michelotti | B6: Qatar Airways Group | C6: Noor Al Marri | D6: Chief Strategy Officer | F6: noor.almarri@sample-2.example | I6: Email | J6: Medium | K6: Low | L6: High | M6: =IF(OR(J6="",K6="",L6=""),"",IF(AND(COUNTIF(J6:L6,"High")>=2,OR(J6="High",L6="High")),"Tier 1",IF(AND(COUNTIF(J6:L6,"High")>=1,COUNTIF(J6:L6,"Medium")>=1),"Tier 2","Tier 3"))) -> Tier 2 | O6: Network planning — interested in route economics and hub connectivity; Regional growth — interested in expansion opportunities across the GCC and adjacent markets. | P6: Tennis — follows major tournaments; Travel — enjoys destinations linked to sport or culture. | Q6: 46184 | S6: =IF(B6="",0,IF(COUNTIF($B$2:$B6,B6)=1,1,0)) -> 0 | T6: =IF(S6=1,SUM($S$2:S6),"") | U6: =IF(W6="",0,IF(COUNTIF($W$2:$W6,W6)=1,1,0)) -> 1 | V6: =IF(U6=1,SUM($U$2:U6),"") -> 5 | W6: =IF(OR(C6="",B6=""),"",TRIM(C6)&"|"&TRIM(B6)) -> Noor Al Marri|Qatar Airways Group
A7: Alberto Michelotti | B7: Qatar Airways Group | C7: Hassan Al Kaabi | D7: Vice President, Strategy | F7: hassan.alkaabi@sample-2.example | I7: Email | J7: High | K7: Low | L7: High | M7: =IF(OR(J7="",K7="",L7=""),"",IF(AND(COUNTIF(J7:L7,"High")>=2,OR(J7="High",L7="High")),"Tier 1",IF(AND(COUNTIF(J7:L7,"High")>=1,COUNTIF(J7:L7,"Medium")>=1),"Tier 2","Tier 3"))) -> Tier 1 | O7: Customer experience — interested in improving the end-to-end passenger journey; Digital aviation — interested in practical uses of digital tools and data in aviation. | P7: Running — enjoys recreational running; Technology — follows consumer technology, wearables and fitness devices. | Q7: 46288 | R7: Had a conversation - no new projects in pipeline | S7: =IF(B7="",0,IF(COUNTIF($B$2:$B7,B7)=1,1,0)) -> 0 | T7: =IF(S7=1,SUM($S$2:S7),"") | U7: =IF(W7="",0,IF(COUNTIF($W$2:$W7,W7)=1,1,0)) -> 1 | V7: =IF(U7=1,SUM($U$2:U7),"") -> 6 | W7: =IF(OR(C7="",B7=""),"",TRIM(C7)&"|"&TRIM(B7)) -> Hassan Al Kaabi|Qatar Airways Group
A8: Eric Guraieb | B8: Qatar National Bank | C8: Layla Al Nuaimi | D8: Chief Executive Officer | F8: layla.alnuaimi@sample-3.example | I8: Email | J8: High | K8: High | L8: High | M8: =IF(OR(J8="",K8="",L8=""),"",IF(AND(COUNTIF(J8:L8,"High")>=2,OR(J8="High",L8="High")),"Tier 1",IF(AND(COUNTIF(J8:L8,"High")>=1,COUNTIF(J8:L8,"Medium")>=1),"Tier 2","Tier 3"))) -> Tier 1 | O8: Capital markets — interested in financing trends and regional capital flows; Corporate banking — interested in how banks deepen relationships with large corporates. | P8: Golf — follows the sport and major events; Economics — enjoys discussing macroeconomic trends, markets and implications for the GCC. | Q8: 46219 | S8: =IF(B8="",0,IF(COUNTIF($B$2:$B8,B8)=1,1,0)) -> 1 | T8: =IF(S8=1,SUM($S$2:S8),"") -> 3 | U8: =IF(W8="",0,IF(COUNTIF($W$2:$W8,W8)=1,1,0)) -> 1 | V8: =IF(U8=1,SUM($U$2:U8),"") -> 7 | W8: =IF(OR(C8="",B8=""),"",TRIM(C8)&"|"&TRIM(B8)) -> Layla Al Nuaimi|Qatar National Bank
A9: Eric Guraieb | B9: Qatar National Bank | C9: Omar Al Ansari | D9: Chief Strategy Officer | F9: omar.alansari@sample-3.example | I9: Email | J9: High | K9: Medium | L9: High | M9: =IF(OR(J9="",K9="",L9=""),"",IF(AND(COUNTIF(J9:L9,"High")>=2,OR(J9="High",L9="High")),"Tier 1",IF(AND(COUNTIF(J9:L9,"High")>=1,COUNTIF(J9:L9,"Medium")>=1),"Tier 2","Tier 3"))) -> Tier 1 | O9: Digital banking — interested in digital business models and fintech partnerships; M&A — interested in the strategic rationale behind banking deals. | P9: Padel — enjoys playing socially; Reading — enjoys business, leadership and current-affairs books. | Q9: 46184 | S9: =IF(B9="",0,IF(COUNTIF($B$2:$B9,B9)=1,1,0)) -> 0 | T9: =IF(S9=1,SUM($S$2:S9),"") | U9: =IF(W9="",0,IF(COUNTIF($W$2:$W9,W9)=1,1,0)) -> 1 | V9: =IF(U9=1,SUM($U$2:U9),"") -> 8 | W9: =IF(OR(C9="",B9=""),"",TRIM(C9)&"|"&TRIM(B9)) -> Omar Al Ansari|Qatar National Bank
A10: Eric Guraieb | B10: Qatar National Bank | C10: Sara Al Farsi | D10: Vice President, Strategy | F10: sara.alfarsi@sample-3.example | I10: Email | J10: High | K10: Medium | L10: High | M10: =IF(OR(J10="",K10="",L10=""),"",IF(AND(COUNTIF(J10:L10,"High")>=2,OR(J10="High",L10="High")),"Tier 1",IF(AND(COUNTIF(J10:L10,"High")>=1,COUNTIF(J10:L10,"Medium")>=1),"Tier 2","Tier 3"))) -> Tier 1 | O10: Payments — interested in digital payments and simpler customer journeys; Wealth management — interested in affluent-customer propositions and trusted advisory relationships. | P10: Art — enjoys exhibitions and galleries; Travel — enjoys culturally rich destinations, local design and architecture. | Q10: 46154 | S10: =IF(B10="",0,IF(COUNTIF($B$2:$B10,B10)=1,1,0)) -> 0 | T10: =IF(S10=1,SUM($S$2:S10),"") | U10: =IF(W10="",0,IF(COUNTIF($W$2:$W10,W10)=1,1,0)) -> 1 | V10: =IF(U10=1,SUM($U$2:U10),"") -> 9 | W10: =IF(OR(C10="",B10=""),"",TRIM(C10)&"|"&TRIM(B10)) -> Sara Al Farsi|Qatar National Bank
A11: Kyle Strong | B11: Ooredoo Qatar | C11: Yousef Al Mulla | D11: Chief Executive Officer | F11: yousef.almulla@sample-4.example | I11: Email | J11: High | K11: Medium | L11: High | M11: =IF(OR(J11="",K11="",L11=""),"",IF(AND(COUNTIF(J11:L11,"High")>=2,OR(J11="High",L11="High")),"Tier 1",IF(AND(COUNTIF(J11:L11,"High")>=1,COUNTIF(J11:L11,"Medium")>=1),"Tier 2","Tier 3"))) -> Tier 1 | O11: 5G — interested in monetising next-generation connectivity; Digital platforms — interested in building adjacent digital services beyond the traditional telecom core. | P11: Football — follows major leagues and competitions; Technology — enjoys useful new devices and consumer technology. | Q11: 46219 | S11: =IF(B11="",0,IF(COUNTIF($B$2:$B11,B11)=1,1,0)) -> 1 | T11: =IF(S11=1,SUM($S$2:S11),"") -> 4 | U11: =IF(W11="",0,IF(COUNTIF($W$2:$W11,W11)=1,1,0)) -> 1 | V11: =IF(U11=1,SUM($U$2:U11),"") -> 10 | W11: =IF(OR(C11="",B11=""),"",TRIM(C11)&"|"&TRIM(B11)) -> Yousef Al Mulla|Ooredoo Qatar
A12: Kyle Strong | B12: Ooredoo Qatar | C12: Aisha Al Hamadi | D12: Chief Strategy Officer | F12: aisha.alhamadi@sample-4.example | I12: Email | J12: High | K12: Low | L12: High | M12: =IF(OR(J12="",K12="",L12=""),"",IF(AND(COUNTIF(J12:L12,"High")>=2,OR(J12="High",L12="High")),"Tier 1",IF(AND(COUNTIF(J12:L12,"High")>=1,COUNTIF(J12:L12,"Medium")>=1),"Tier 2","Tier 3"))) -> Tier 1 | O12: AI and analytics — interested in practical AI applications and data-led decision-making; B2B growth — interested in scaling enterprise digital services. | P12: Cycling — enjoys recreational cycling; Podcasts — listens to business, technology and leadership podcasts. | Q12: 46184 | S12: =IF(B12="",0,IF(COUNTIF($B$2:$B12,B12)=1,1,0)) -> 0 | T12: =IF(S12=1,SUM($S$2:S12),"") | U12: =IF(W12="",0,IF(COUNTIF($W$2:$W12,W12)=1,1,0)) -> 1 | V12: =IF(U12=1,SUM($U$2:U12),"") -> 11 | W12: =IF(OR(C12="",B12=""),"",TRIM(C12)&"|"&TRIM(B12)) -> Aisha Al Hamadi|Ooredoo Qatar
A13: Kyle Strong | B13: Ooredoo Qatar | C13: Rashid Al Jaber | D13: Vice President, Strategy | F13: rashid.aljaber@sample-4.example | I13: Email | J13: High | K13: Low | L13: High | M13: =IF(OR(J13="",K13="",L13=""),"",IF(AND(COUNTIF(J13:L13,"High")>=2,OR(J13="High",L13="High")),"Tier 1",IF(AND(COUNTIF(J13:L13,"High")>=1,COUNTIF(J13:L13,"Medium")>=1),"Tier 2","Tier 3"))) -> Tier 1 | O13: Customer experience — interested in creating simple digital journeys; Cybersecurity — interested in trust, privacy and cyber resilience. | P13: Running — enjoys recreational running; Photography — enjoys city, travel or event-based photography. | Q13: 46154 | S13: =IF(B13="",0,IF(COUNTIF($B$2:$B13,B13)=1,1,0)) -> 0 | T13: =IF(S13=1,SUM($S$2:S13),"") | U13: =IF(W13="",0,IF(COUNTIF($W$2:$W13,W13)=1,1,0)) -> 1 | V13: =IF(U13=1,SUM($U$2:U13),"") -> 12 | W13: =IF(OR(C13="",B13=""),"",TRIM(C13)&"|"&TRIM(B13)) -> Rashid Al Jaber|Ooredoo Qatar
A14: Sergey Glushkin | B14: Industries Qatar | C14: Dana Al Mazrouei | D14: Vice President, Strategy | F14: dana.almazrouei@sample-5.example | I14: Email | J14: Medium | K14: High | L14: High | M14: =IF(OR(J14="",K14="",L14=""),"",IF(AND(COUNTIF(J14:L14,"High")>=2,OR(J14="High",L14="High")),"Tier 1",IF(AND(COUNTIF(J14:L14,"High")>=1,COUNTIF(J14:L14,"Medium")>=1),"Tier 2","Tier 3"))) -> Tier 1 | O14: Petrochemicals — interested in industry competitiveness and future economics; Industrial decarbonisation — interested in lower-carbon production in energy-intensive industries. | P14: Sailing — enjoys maritime experiences and sailing events; Travel — enjoys coastal and waterfront destinations. | Q14: 46219 | S14: =IF(B14="",0,IF(COUNTIF($B$2:$B14,B14)=1,1,0)) -> 1 | T14: =IF(S14=1,SUM($S$2:S14),"") -> 5 | U14: =IF(W14="",0,IF(COUNTIF($W$2:$W14,W14)=1,1,0)) -> 1 | V14: =IF(U14=1,SUM($U$2:U14),"") -> 13 | W14: =IF(OR(C14="",B14=""),"",TRIM(C14)&"|"&TRIM(B14)) -> Dana Al Mazrouei|Industries Qatar
A15: Sergey Glushkin | B15: Industries Qatar | C15: Tariq Al Sayed | D15: Director, Transformation | F15: tariq.alsayed@sample-5.example | I15: Email | J15: High | K15: Medium | L15: High | M15: =IF(OR(J15="",K15="",L15=""),"",IF(AND(COUNTIF(J15:L15,"High")>=2,OR(J15="High",L15="High")),"Tier 1",IF(AND(COUNTIF(J15:L15,"High")>=1,COUNTIF(J15:L15,"Medium")>=1),"Tier 2","Tier 3"))) -> Tier 1 | O15: Digital manufacturing — interested in automation and technology-enabled operations; Operational excellence — interested in plant productivity and measurable performance improvement. | P15: Golf — follows major tournaments; Formula 1 — follows races and is interested in performance, engineering and strategy. | Q15: 46184 | S15: =IF(B15="",0,IF(COUNTIF($B$2:$B15,B15)=1,1,0)) -> 0 | T15: =IF(S15=1,SUM($S$2:S15),"") | U15: =IF(W15="",0,IF(COUNTIF($W$2:$W15,W15)=1,1,0)) -> 1 | V15: =IF(U15=1,SUM($U$2:U15),"") -> 14 | W15: =IF(OR(C15="",B15=""),"",TRIM(C15)&"|"&TRIM(B15)) -> Tariq Al Sayed|Industries Qatar
A16: Sergey Glushkin | B16: Industries Qatar | C16: Lina Al Mansoori | D16: Senior Manager, Strategy | F16: lina.almansoori@sample-5.example | I16: Email | J16: Medium | K16: Medium | L16: High | M16: =IF(OR(J16="",K16="",L16=""),"",IF(AND(COUNTIF(J16:L16,"High")>=2,OR(J16="High",L16="High")),"Tier 1",IF(AND(COUNTIF(J16:L16,"High")>=1,COUNTIF(J16:L16,"Medium")>=1),"Tier 2","Tier 3"))) -> Tier 2 | O16: Supply-chain resilience — interested in supplier risk and reliability; Capital projects — interested in effective delivery of major industrial investments. | P16: Hiking — enjoys accessible outdoor trails; Reading — enjoys books on business, history and current affairs. | Q16: 46154 | R16: Had a conversation- Might have a new project in pipeline | S16: =IF(B16="",0,IF(COUNTIF($B$2:$B16,B16)=1,1,0)) -> 0 | T16: =IF(S16=1,SUM($S$2:S16),"") | U16: =IF(W16="",0,IF(COUNTIF($W$2:$W16,W16)=1,1,0)) -> 1 | V16: =IF(U16=1,SUM($U$2:U16),"") -> 15 | W16: =IF(OR(C16="",B16=""),"",TRIM(C16)&"|"&TRIM(B16)) -> Lina Al Mansoori|Industries Qatar
A17: Alberto Michelotti | B17: Commercial Bank of Qatar | C17: Moza Al Kuwari | D17: Vice President, Strategy | F17: moza.alkuwari@sample-6.example | I17: Email | J17: Medium | K17: Medium | L17: High | M17: =IF(OR(J17="",K17="",L17=""),"",IF(AND(COUNTIF(J17:L17,"High")>=2,OR(J17="High",L17="High")),"Tier 1",IF(AND(COUNTIF(J17:L17,"High")>=1,COUNTIF(J17:L17,"Medium")>=1),"Tier 2","Tier 3"))) -> Tier 2 | O17: SME banking — interested in improving propositions and financing for growing businesses; Digital banking — interested in digital onboarding and simpler customer journeys. | P17: Padel — enjoys playing socially; Travel — enjoys short regional trips and city breaks. | Q17: 46199 | S17: =IF(B17="",0,IF(COUNTIF($B$2:$B17,B17)=1,1,0)) -> 1 | T17: =IF(S17=1,SUM($S$2:S17),"") -> 6 | U17: =IF(W17="",0,IF(COUNTIF($W$2:$W17,W17)=1,1,0)) -> 1 | V17: =IF(U17=1,SUM($U$2:U17),"") -> 16 | W17: =IF(OR(C17="",B17=""),"",TRIM(C17)&"|"&TRIM(B17)) -> Moza Al Kuwari|Commercial Bank of Qatar
A18: Alberto Michelotti | B18: Commercial Bank of Qatar | C18: Saeed Al Romaihi | D18: Director, Transformation | F18: saeed.alromaihi@sample-6.example | I18: Email | J18: Medium | K18: Low | L18: High | M18: =IF(OR(J18="",K18="",L18=""),"",IF(AND(COUNTIF(J18:L18,"High")>=2,OR(J18="High",L18="High")),"Tier 1",IF(AND(COUNTIF(J18:L18,"High")>=1,COUNTIF(J18:L18,"Medium")>=1),"Tier 2","Tier 3"))) -> Tier 2 | O18: Banking transformation — interested in simplifying operations and improving service; Process automation — interested in digitising workflows and improving efficiency. | P18: Cycling — enjoys recreational cycling; Technology — follows technology related to mobility, fitness and productivity. | Q18: 46109 | S18: =IF(B18="",0,IF(COUNTIF($B$2:$B18,B18)=1,1,0)) -> 0 | T18: =IF(S18=1,SUM($S$2:S18),"") | U18: =IF(W18="",0,IF(COUNTIF($W$2:$W18,W18)=1,1,0)) -> 1 | V18: =IF(U18=1,SUM($U$2:U18),"") -> 17 | W18: =IF(OR(C18="",B18=""),"",TRIM(C18)&"|"&TRIM(B18)) -> Saeed Al Romaihi|Commercial Bank of Qatar
A19: Alberto Michelotti | B19: Commercial Bank of Qatar | C19: Hessa Al Hajri | D19: Senior Manager, Strategy | F19: hessa.alhajri@sample-6.example | I19: Email | J19: Medium | K19: Low | L19: High | M19: =IF(OR(J19="",K19="",L19=""),"",IF(AND(COUNTIF(J19:L19,"High")>=2,OR(J19="High",L19="High")),"Tier 1",IF(AND(COUNTIF(J19:L19,"High")>=1,COUNTIF(J19:L19,"Medium")>=1),"Tier 2","Tier 3"))) -> Tier 2 | O19: Payments — interested in frictionless payment journeys; Customer experience — interested in using customer insight to improve everyday banking interactions. | P19: Cooking — enjoys trying new recipes and regional cuisines; Photography — enjoys food and travel photography. | Q19: 46009 | S19: =IF(B19="",0,IF(COUNTIF($B$2:$B19,B19)=1,1,0)) -> 0 | T19: =IF(S19=1,SUM($S$2:S19),"") | U19: =IF(W19="",0,IF(COUNTIF($W$2:$W19,W19)=1,1,0)) -> 1 | V19: =IF(U19=1,SUM($U$2:U19),"") -> 18 | W19: =IF(OR(C19="",B19=""),"",TRIM(C19)&"|"&TRIM(B19)) -> Hessa Al Hajri|Commercial Bank of Qatar
A20: Eric Guraieb | B20: Doha Bank | C20: Jassim Al Subaie | D20: Chief Executive Officer | F20: jassim.alsubaie@sample-7.example | I20: Email | J20: High | K20: Medium | L20: Medium | M20: =IF(OR(J20="",K20="",L20=""),"",IF(AND(COUNTIF(J20:L20,"High")>=2,OR(J20="High",L20="High")),"Tier 1",IF(AND(COUNTIF(J20:L20,"High")>=1,COUNTIF(J20:L20,"Medium")>=1),"Tier 2","Tier 3"))) -> Tier 2 | O20: Capital markets — interested in funding, liquidity and changing market conditions; Balance-sheet strategy — interested in asset allocation and navigating different rate environments. | P20: Golf — follows major competitions; Football — follows major teams, players and events. | Q20: 46199 | S20: =IF(B20="",0,IF(COUNTIF($B$2:$B20,B20)=1,1,0)) -> 1 | T20: =IF(S20=1,SUM($S$2:S20),"") -> 7 | U20: =IF(W20="",0,IF(COUNTIF($W$2:$W20,W20)=1,1,0)) -> 1 | V20: =IF(U20=1,SUM($U$2:U20),"") -> 19 | W20: =IF(OR(C20="",B20=""),"",TRIM(C20)&"|"&TRIM(B20)) -> Jassim Al Subaie|Doha Bank
A21: Eric Guraieb | B21: Doha Bank | C21: Reem Al Khulaifi | D21: Chief Strategy Officer | F21: reem.alkhulaifi@sample-7.example | I21: Email | J21: High | K21: Low | L21: Medium | M21: =IF(OR(J21="",K21="",L21=""),"",IF(AND(COUNTIF(J21:L21,"High")>=2,OR(J21="High",L21="High")),"Tier 1",IF(AND(COUNTIF(J21:L21,"High")>=1,COUNTIF(J21:L21,"Medium")>=1),"Tier 2","Tier 3"))) -> Tier 2 | O21: Corporate banking — interested in sector-led client growth and transaction opportunities; M&A — interested in the strategic logic behind regional deals. | P21: Reading — enjoys business and current-affairs books; Travel — enjoys culturally interesting destinations and city breaks. | Q21: 46109 | S21: =IF(B21="",0,IF(COUNTIF($B$2:$B21,B21)=1,1,0)) -> 0 | T21: =IF(S21=1,SUM($S$2:S21),"") | U21: =IF(W21="",0,IF(COUNTIF($W$2:$W21,W21)=1,1,0)) -> 1 | V21: =IF(U21=1,SUM($U$2:U21),"") -> 20 | W21: =IF(OR(C21="",B21=""),"",TRIM(C21)&"|"&TRIM(B21)) -> Reem Al Khulaifi|Doha Bank
A22: Eric Guraieb | B22: Doha Bank | C22: Abdulla Al Dosari | D22: Vice President, Strategy | F22: abdulla.aldosari@sample-7.example | I22: Email | J22: High | K22: Low | L22: Medium | M22: =IF(OR(J22="",K22="",L22=""),"",IF(AND(COUNTIF(J22:L22,"High")>=2,OR(J22="High",L22="High")),"Tier 1",IF(AND(COUNTIF(J22:L22,"High")>=1,COUNTIF(J22:L22,"Medium")>=1),"Tier 2","Tier 3"))) -> Tier 2 | O22: Risk and regulation — interested in compliance, resilience and sound risk management; Digital banking — interested in balancing digital innovation with appropriate controls. | P22: Running — enjoys recreational running; Padel — enjoys playing socially and follows local events. | Q22: 46009 | R22: Meeting fixed for next month | S22: =IF(B22="",0,IF(COUNTIF($B$2:$B22,B22)=1,1,0)) -> 0 | T22: =IF(S22=1,SUM($S$2:S22),"") | U22: =IF(W22="",0,IF(COUNTIF($W$2:$W22,W22)=1,1,0)) -> 1 | V22: =IF(U22=1,SUM($U$2:U22),"") -> 21 | W22: =IF(OR(C22="",B22=""),"",TRIM(C22)&"|"&TRIM(B22)) -> Abdulla Al Dosari|Doha Bank
A23: Kyle Strong | B23: Qatar Insurance Company | C23: Fatima Al Mohannadi | D23: Vice President, Strategy | F23: fatima.almohannadi@sample-8.example | I23: Email | J23: Medium | K23: High | L23: Medium | M23: =IF(OR(J23="",K23="",L23=""),"",IF(AND(COUNTIF(J23:L23,"High")>=2,OR(J23="High",L23="High")),"Tier 1",IF(AND(COUNTIF(J23:L23,"High")>=1,COUNTIF(J23:L23,"Medium")>=1),"Tier 2","Tier 3"))) -> Tier 2 | O23: InsurTech — interested in digital insurance models; Climate risk — interested in climate-related exposure and new approaches to pricing and managing risk. | P23: Tennis — follows major tournaments; Art — enjoys exhibitions, galleries and contemporary art. | Q23: 46199 | S23: =IF(B23="",0,IF(COUNTIF($B$2:$B23,B23)=1,1,0)) -> 1 | T23: =IF(S23=1,SUM($S$2:S23),"") -> 8 | U23: =IF(W23="",0,IF(COUNTIF($W$2:$W23,W23)=1,1,0)) -> 1 | V23: =IF(U23=1,SUM($U$2:U23),"") -> 22 | W23: =IF(OR(C23="",B23=""),"",TRIM(C23)&"|"&TRIM(B23)) -> Fatima Al Mohannadi|Qatar Insurance Company
A24: Kyle Strong | B24: Qatar Insurance Company | C24: Hamad Al Nasr | D24: Director, Transformation | F24: hamad.alnasr@sample-8.example | I24: Email | J24: Medium | K24: Medium | L24: Medium | M24: =IF(OR(J24="",K24="",L24=""),"",IF(AND(COUNTIF(J24:L24,"High")>=2,OR(J24="High",L24="High")),"Tier 1",IF(AND(COUNTIF(J24:L24,"High")>=1,COUNTIF(J24:L24,"Medium")>=1),"Tier 2","Tier 3"))) -> Tier 3 | O24: Underwriting transformation — interested in modernising underwriting processes; Risk analytics — interested in data-led risk selection and pricing. | P24: Cycling — enjoys cycling and scenic routes; Travel — enjoys outdoor and destination-based trips. | Q24: 46109 | S24: =IF(B24="",0,IF(COUNTIF($B$2:$B24,B24)=1,1,0)) -> 0 | T24: =IF(S24=1,SUM($S$2:S24),"") | U24: =IF(W24="",0,IF(COUNTIF($W$2:$W24,W24)=1,1,0)) -> 1 | V24: =IF(U24=1,SUM($U$2:U24),"") -> 23 | W24: =IF(OR(C24="",B24=""),"",TRIM(C24)&"|"&TRIM(B24)) -> Hamad Al Nasr|Qatar Insurance Company
A25: Kyle Strong | B25: Qatar Insurance Company | C25: Shaikha Al Muftah | D25: Senior Manager, Strategy | F25: shaikha.almuftah@sample-8.example | I25: Email | J25: Medium | K25: Medium | L25: Medium | M25: =IF(OR(J25="",K25="",L25=""),"",IF(AND(COUNTIF(J25:L25,"High")>=2,OR(J25="High",L25="High")),"Tier 1",IF(AND(COUNTIF(J25:L25,"High")>=1,COUNTIF(J25:L25,"Medium")>=1),"Tier 2","Tier 3"))) -> Tier 3 | O25: Distribution strategy — interested in digital and partner channels; Customer experience — interested in retention and simpler insurance journeys. | P25: Cooking — enjoys exploring recipes; Reading — reads across business, culture and current affairs. | Q25: 46009 | S25: =IF(B25="",0,IF(COUNTIF($B$2:$B25,B25)=1,1,0)) -> 0 | T25: =IF(S25=1,SUM($S$2:S25),"") | U25: =IF(W25="",0,IF(COUNTIF($W$2:$W25,W25)=1,1,0)) -> 1 | V25: =IF(U25=1,SUM($U$2:U25),"") -> 24 | W25: =IF(OR(C25="",B25=""),"",TRIM(C25)&"|"&TRIM(B25)) -> Shaikha Al Muftah|Qatar Insurance Company
A26: Sergey Glushkin | B26: Nakilat | C26: Bader Al Emadi | D26: Vice President, Strategy | F26: bader.alemadi@sample-9.example | I26: Email | J26: Medium | K26: Medium | L26: High | M26: =IF(OR(J26="",K26="",L26=""),"",IF(AND(COUNTIF(J26:L26,"High")>=2,OR(J26="High",L26="High")),"Tier 1",IF(AND(COUNTIF(J26:L26,"High")>=1,COUNTIF(J26:L26,"Medium")>=1),"Tier 2","Tier 3"))) -> Tier 2 | O26: Sustainability — interested in lower-emission maritime operations; Green shipping — interested in alternative fuels and the commercial path to greener fleets. | P26: Sailing — enjoys maritime activities; Environmental volunteering — interested in conservation and coastal community initiatives. | Q26: 46199 | S26: =IF(B26="",0,IF(COUNTIF($B$2:$B26,B26)=1,1,0)) -> 1 | T26: =IF(S26=1,SUM($S$2:S26),"") -> 9 | U26: =IF(W26="",0,IF(COUNTIF($W$2:$W26,W26)=1,1,0)) -> 1 | V26: =IF(U26=1,SUM($U$2:U26),"") -> 25 | W26: =IF(OR(C26="",B26=""),"",TRIM(C26)&"|"&TRIM(B26)) -> Bader Al Emadi|Nakilat
A27: Sergey Glushkin | B27: Nakilat | C27: Maryam Al Rayes | D27: Director, Transformation | F27: maryam.alrayes@sample-9.example | I27: Email | J27: Medium | K27: Low | L27: High | M27: =IF(OR(J27="",K27="",L27=""),"",IF(AND(COUNTIF(J27:L27,"High")>=2,OR(J27="High",L27="High")),"Tier 1",IF(AND(COUNTIF(J27:L27,"High")>=1,COUNTIF(J27:L27,"Medium")>=1),"Tier 2","Tier 3"))) -> Tier 2 | O27: Fleet renewal — interested in vessel investment and modernisation choices; Maritime decarbonisation — interested in fuel transition and lower-emission shipping. | P27: Photography — enjoys coastal and landscape photography; Travel — enjoys destinations with a strong maritime character. | Q27: 46109 | R27: Meeting fixed for next week | S27: =IF(B27="",0,IF(COUNTIF($B$2:$B27,B27)=1,1,0)) -> 0 | T27: =IF(S27=1,SUM($S$2:S27),"") | U27: =IF(W27="",0,IF(COUNTIF($W$2:$W27,W27)=1,1,0)) -> 1 | V27: =IF(U27=1,SUM($U$2:U27),"") -> 26 | W27: =IF(OR(C27="",B27=""),"",TRIM(C27)&"|"&TRIM(B27)) -> Maryam Al Rayes|Nakilat
A28: Naveed Vakil | B28: United Development Company | C28: Noura Al Derham | D28: Chief Executive Officer | F28: noura.alderham@sample-10.example | I28: Email | J28: High | K28: Medium | L28: Medium | M28: =IF(OR(J28="",K28="",L28=""),"",IF(AND(COUNTIF(J28:L28,"High")>=2,OR(J28="High",L28="High")),"Tier 1",IF(AND(COUNTIF(J28:L28,"High")>=1,COUNTIF(J28:L28,"Medium")>=1),"Tier 2","Tier 3"))) -> Tier 2 | O28: Real-estate growth — interested in destination development and portfolio performance; Operational excellence — interested in delivering high-quality resident and visitor experiences. | P28: Running — enjoys active outdoor running; Sailing — follows or participates in sailing and local maritime events. | Q28: 46199 | S28: =IF(B28="",0,IF(COUNTIF($B$2:$B28,B28)=1,1,0)) -> 1 | T28: =IF(S28=1,SUM($S$2:S28),"") -> 10 | U28: =IF(W28="",0,IF(COUNTIF($W$2:$W28,W28)=1,1,0)) -> 1 | V28: =IF(U28=1,SUM($U$2:U28),"") -> 27 | W28: =IF(OR(C28="",B28=""),"",TRIM(C28)&"|"&TRIM(B28)) -> Noura Al Derham|United Development Company
A29: Naveed Vakil | B29: United Development Company | C29: Waleed Al Khater | D29: Chief Strategy Officer | F29: waleed.alkhater@sample-10.example | I29: Email | J29: High | K29: Low | L29: Medium | M29: =IF(OR(J29="",K29="",L29=""),"",IF(AND(COUNTIF(J29:L29,"High")>=2,OR(J29="High",L29="High")),"Tier 1",IF(AND(COUNTIF(J29:L29,"High")>=1,COUNTIF(J29:L29,"Medium")>=1),"Tier 2","Tier 3"))) -> Tier 2 | O29: Urban development — interested in placemaking and the evolution of mixed-use destinations; Real-estate investment — interested in portfolio returns and investment opportunities. | P29: Architecture — enjoys contemporary architecture and design-led developments; Art — enjoys exhibitions connected to urban culture. | Q29: 46109 | S29: =IF(B29="",0,IF(COUNTIF($B$2:$B29,B29)=1,1,0)) -> 0 | T29: =IF(S29=1,SUM($S$2:S29),"") | U29: =IF(W29="",0,IF(COUNTIF($W$2:$W29,W29)=1,1,0)) -> 1 | V29: =IF(U29=1,SUM($U$2:U29),"") -> 28 | W29: =IF(OR(C29="",B29=""),"",TRIM(C29)&"|"&TRIM(B29)) -> Waleed Al Khater|United Development Company
A30: Naveed Vakil | B30: United Development Company | C30: Hind Al Qasimi | D30: Vice President, Strategy | F30: hind.alqasimi@sample-10.example | I30: Email | J30: High | K30: Low | L30: Medium | M30: =IF(OR(J30="",K30="",L30=""),"",IF(AND(COUNTIF(J30:L30,"High")>=2,OR(J30="High",L30="High")),"Tier 1",IF(AND(COUNTIF(J30:L30,"High")>=1,COUNTIF(J30:L30,"Medium")>=1),"Tier 2","Tier 3"))) -> Tier 2 | O30: Smart cities — interested in connected communities and digital infrastructure; Mixed-use development — interested in integrated residential, retail and hospitality destinations. | P30: Golf — follows the sport; Travel — enjoys well-designed resorts, cities and leisure destinations. | Q30: 46009 | S30: =IF(B30="",0,IF(COUNTIF($B$2:$B30,B30)=1,1,0)) -> 0 | T30: =IF(S30=1,SUM($S$2:S30),"") | U30: =IF(W30="",0,IF(COUNTIF($W$2:$W30,W30)=1,1,0)) -> 1 | V30: =IF(U30=1,SUM($U$2:U30),"") -> 29 | W30: =IF(OR(C30="",B30=""),"",TRIM(C30)&"|"&TRIM(B30)) -> Hind Al Qasimi|United Development Company
A31: Reda Jennane | B31: Milaha | C31: Majed Al Shafi | D31: Vice President, Strategy | F31: majed.alshafi@sample-11.example | I31: Email | J31: Medium | K31: Medium | L31: Medium | M31: =IF(OR(J31="",K31="",L31=""),"",IF(AND(COUNTIF(J31:L31,"High")>=2,OR(J31="High",L31="High")),"Tier 1",IF(AND(COUNTIF(J31:L31,"High")>=1,COUNTIF(J31:L31,"Medium")>=1),"Tier 2","Tier 3"))) -> Tier 3 | O31: Sustainable logistics — interested in lower-carbon operations; Customer experience — interested in making shipping and logistics services easier for customers. | P31: Photography — enjoys visual storytelling and architecture; Design — interested in product and service design. | Q31: 46139 | S31: =IF(B31="",0,IF(COUNTIF($B$2:$B31,B31)=1,1,0)) -> 1 | T31: =IF(S31=1,SUM($S$2:S31),"") -> 11 | U31: =IF(W31="",0,IF(COUNTIF($W$2:$W31,W31)=1,1,0)) -> 1 | V31: =IF(U31=1,SUM($U$2:U31),"") -> 30 | W31: =IF(OR(C31="",B31=""),"",TRIM(C31)&"|"&TRIM(B31)) -> Majed Al Shafi|Milaha
A32: Reda Jennane | B32: Milaha | C32: Jawaher Al Murikhi | D32: Director, Transformation | F32: jawaher.almurikhi@sample-11.example | I32: Email | J32: Medium | K32: Low | L32: Medium | M32: =IF(OR(J32="",K32="",L32=""),"",IF(AND(COUNTIF(J32:L32,"High")>=2,OR(J32="High",L32="High")),"Tier 1",IF(AND(COUNTIF(J32:L32,"High")>=1,COUNTIF(J32:L32,"Medium")>=1),"Tier 2","Tier 3"))) -> Tier 3 | O32: M&A — interested in the rationale behind shipping and logistics deals; Fleet financing — interested in asset-backed financing and investment choices. | P32: Golf — follows the sport; Sailing — enjoys maritime and coastal events and destinations. | Q32: 45979 | S32: =IF(B32="",0,IF(COUNTIF($B$2:$B32,B32)=1,1,0)) -> 0 | T32: =IF(S32=1,SUM($S$2:S32),"") | U32: =IF(W32="",0,IF(COUNTIF($W$2:$W32,W32)=1,1,0)) -> 1 | V32: =IF(U32=1,SUM($U$2:U32),"") -> 31 | W32: =IF(OR(C32="",B32=""),"",TRIM(C32)&"|"&TRIM(B32)) -> Jawaher Al Murikhi|Milaha
A33: Reda Jennane | B33: Milaha | C33: Thamer Al Misnad | D33: Senior Manager, Strategy | F33: thamer.almisnad@sample-11.example | I33: Email | J33: Medium | K33: Low | L33: Medium | M33: =IF(OR(J33="",K33="",L33=""),"",IF(AND(COUNTIF(J33:L33,"High")>=2,OR(J33="High",L33="High")),"Tier 1",IF(AND(COUNTIF(J33:L33,"High")>=1,COUNTIF(J33:L33,"Medium")>=1),"Tier 2","Tier 3"))) -> Tier 3 | O33: Digital transformation — interested in using technology and data to improve operations; Port operations — interested in automation and efficiency across maritime and logistics networks. | P33: Padel — enjoys playing socially; Technology — follows useful digital tools, devices and emerging technology. | Q33: 45809 | S33: =IF(B33="",0,IF(COUNTIF($B$2:$B33,B33)=1,1,0)) -> 0 | T33: =IF(S33=1,SUM($S$2:S33),"") | U33: =IF(W33="",0,IF(COUNTIF($W$2:$W33,W33)=1,1,0)) -> 1 | V33: =IF(U33=1,SUM($U$2:U33),"") -> 32 | W33: =IF(OR(C33="",B33=""),"",TRIM(C33)&"|"&TRIM(B33)) -> Thamer Al Misnad|Milaha
A34: Riccardo Terruzzi | B34: Baladna | C34: Latifa Al Shamlan | D34: Vice President, Strategy | F34: latifa.alshamlan@sample-12.example | I34: Email | J34: Medium | K34: Low | L34: Low | M34: =IF(OR(J34="",K34="",L34=""),"",IF(AND(COUNTIF(J34:L34,"High")>=2,OR(J34="High",L34="High")),"Tier 1",IF(AND(COUNTIF(J34:L34,"High")>=1,COUNTIF(J34:L34,"Medium")>=1),"Tier 2","Tier 3"))) -> Tier 3 | O34: Regional growth — interested in market expansion across the GCC; Food-sector strategy — interested in food security and scaling consumer brands. | P34: Football — follows major competitions; Travel — enjoys trips linked to events, culture and new destinations. | Q34: 46139 | S34: =IF(B34="",0,IF(COUNTIF($B$2:$B34,B34)=1,1,0)) -> 1 | T34: =IF(S34=1,SUM($S$2:S34),"") -> 12 | U34: =IF(W34="",0,IF(COUNTIF($W$2:$W34,W34)=1,1,0)) -> 1 | V34: =IF(U34=1,SUM($U$2:U34),"") -> 33 | W34: =IF(OR(C34="",B34=""),"",TRIM(C34)&"|"&TRIM(B34)) -> Latifa Al Shamlan|Baladna
A35: Riccardo Terruzzi | B35: Baladna | C35: Mansour Al Dehaimi | D35: Director, Transformation | F35: mansour.aldehaimi@sample-12.example | I35: Email | J35: Medium | K35: Low | L35: Low | M35: =IF(OR(J35="",K35="",L35=""),"",IF(AND(COUNTIF(J35:L35,"High")>=2,OR(J35="High",L35="High")),"Tier 1",IF(AND(COUNTIF(J35:L35,"High")>=1,COUNTIF(J35:L35,"Medium")>=1),"Tier 2","Tier 3"))) -> Tier 3 | O35: Food security — interested in resilient local supply; Consumer growth — interested in brand building and expanding dairy and food propositions. | P35: Cooking — enjoys food and healthy recipes; Wellness — interested in practical fitness and wellbeing. | Q35: 45979 | S35: =IF(B35="",0,IF(COUNTIF($B$2:$B35,B35)=1,1,0)) -> 0 | T35: =IF(S35=1,SUM($S$2:S35),"") | U35: =IF(W35="",0,IF(COUNTIF($W$2:$W35,W35)=1,1,0)) -> 1 | V35: =IF(U35=1,SUM($U$2:U35),"") -> 34 | W35: =IF(OR(C35="",B35=""),"",TRIM(C35)&"|"&TRIM(B35)) -> Mansour Al Dehaimi|Baladna
A36: Riccardo Terruzzi | B36: Baladna | C36: Meirah Al Obaidly | D36: Senior Manager, Strategy | F36: meirah.alobaidly@sample-12.example | I36: Email | J36: Medium | K36: Low | L36: Low | M36: =IF(OR(J36="",K36="",L36=""),"",IF(AND(COUNTIF(J36:L36,"High")>=2,OR(J36="High",L36="High")),"Tier 1",IF(AND(COUNTIF(J36:L36,"High")>=1,COUNTIF(J36:L36,"Medium")>=1),"Tier 2","Tier 3"))) -> Tier 3 | O36: Supply-chain transformation — interested in availability, forecasting and supply performance; Digital commerce — interested in direct-to-consumer growth in food and retail. | P36: Running — enjoys recreational running; Photography — enjoys landscapes, city life and travel photography. | Q36: 45809 | S36: =IF(B36="",0,IF(COUNTIF($B$2:$B36,B36)=1,1,0)) -> 0 | T36: =IF(S36=1,SUM($S$2:S36),"") | U36: =IF(W36="",0,IF(COUNTIF($W$2:$W36,W36)=1,1,0)) -> 1 | V36: =IF(U36=1,SUM($U$2:U36),"") -> 35 | W36: =IF(OR(C36="",B36=""),"",TRIM(C36)&"|"&TRIM(B36)) -> Meirah Al Obaidly|Baladna
A37: Stanislav Gaiduk | B37: Emirates Group | C37: Khalifa Al Yafei | D37: Senior Manager, Strategy | F37: khalifa.alyafei@sample-13.example | I37: Email | J37: Low | K37: Medium | L37: Low | M37: =IF(OR(J37="",K37="",L37=""),"",IF(AND(COUNTIF(J37:L37,"High")>=2,OR(J37="High",L37="High")),"Tier 1",IF(AND(COUNTIF(J37:L37,"High")>=1,COUNTIF(J37:L37,"Medium")>=1),"Tier 2","Tier 3"))) -> Tier 3 | O37: Route-to-market — interested in stronger commercial channels and service consistency; Operational excellence — interested in productivity across complex aviation operations. | P37: Football — follows major competitions; Travel — enjoys destinations with sporting or cultural appeal. | Q37: 46139 | S37: =IF(B37="",0,IF(COUNTIF($B$2:$B37,B37)=1,1,0)) -> 1 | T37: =IF(S37=1,SUM($S$2:S37),"") -> 13 | U37: =IF(W37="",0,IF(COUNTIF($W$2:$W37,W37)=1,1,0)) -> 1 | V37: =IF(U37=1,SUM($U$2:U37),"") -> 36 | W37: =IF(OR(C37="",B37=""),"",TRIM(C37)&"|"&TRIM(B37)) -> Khalifa Al Yafei|Emirates Group
A38: Stanislav Gaiduk | B38: Emirates Group | C38: Wafa Al Humaid | D38: Manager, Transformation | F38: wafa.alhumaid@sample-13.example | I38: Email | J38: Low | K38: Low | L38: Low | M38: =IF(OR(J38="",K38="",L38=""),"",IF(AND(COUNTIF(J38:L38,"High")>=2,OR(J38="High",L38="High")),"Tier 1",IF(AND(COUNTIF(J38:L38,"High")>=1,COUNTIF(J38:L38,"Medium")>=1),"Tier 2","Tier 3"))) -> Tier 3 | O38: Aviation sustainability — interested in lower-carbon flying; Network planning — interested in route economics and balancing growth with environmental goals. | P38: Tennis — follows major events; Travel — enjoys trips connected to culture, food or live sport. | Q38: 45979 | S38: =IF(B38="",0,IF(COUNTIF($B$2:$B38,B38)=1,1,0)) -> 0 | T38: =IF(S38=1,SUM($S$2:S38),"") | U38: =IF(W38="",0,IF(COUNTIF($W$2:$W38,W38)=1,1,0)) -> 1 | V38: =IF(U38=1,SUM($U$2:U38),"") -> 37 | W38: =IF(OR(C38="",B38=""),"",TRIM(C38)&"|"&TRIM(B38)) -> Wafa Al Humaid|Emirates Group
A39: Stanislav Gaiduk | B39: Emirates Group | C39: Nasser Al Khaldi | D39: Program Manager | F39: nasser.alkhaldi@sample-13.example | I39: Email | J39: Low | K39: Low | L39: Low | M39: =IF(OR(J39="",K39="",L39=""),"",IF(AND(COUNTIF(J39:L39,"High")>=2,OR(J39="High",L39="High")),"Tier 1",IF(AND(COUNTIF(J39:L39,"High")>=1,COUNTIF(J39:L39,"Medium")>=1),"Tier 2","Tier 3"))) -> Tier 3 | O39: Digital transformation — interested in using technology and data to improve travel; Customer experience — interested in loyalty and simpler passenger journeys. | P39: Cycling — enjoys cycling; Technology — follows mobility, wearables and consumer technology. | Q39: 45809 | S39: =IF(B39="",0,IF(COUNTIF($B$2:$B39,B39)=1,1,0)) -> 0 | T39: =IF(S39=1,SUM($S$2:S39),"") | U39: =IF(W39="",0,IF(COUNTIF($W$2:$W39,W39)=1,1,0)) -> 1 | V39: =IF(U39=1,SUM($U$2:U39),"") -> 38 | W39: =IF(OR(C39="",B39=""),"",TRIM(C39)&"|"&TRIM(B39)) -> Nasser Al Khaldi|Emirates Group
... A45: Meher Ben Marzouk | B45: Emaar Properties | C45: Zayed Al Rashdi | D45: Senior Manager, Strategy | F45: zayed.alrashdi@sample-15.example | I45: Email | J45: Medium | K45: Low | L45: Low | M45: =IF(OR(J45="",K45="",L45=""),"",IF(AND(COUNTIF(J45:L45,"High")>=2,OR(J45="High",L45="High")),"Tier 1",IF(AND(COUNTIF(J45:L45,"High")>=1,COUNTIF(J45:L45,"Medium")>=1),"Tier 2","Tier 3"))) -> Tier 3 | O45: Smart cities — interested in connected communities; Digital sales — interested in data-led customer acquisition and digital journeys for property buyers. | P45: Photography — enjoys photography linked to cities and travel; Design — interested in architecture, visual design and the built environment. | Q45: 45809 | S45: =IF(B45="",0,IF(COUNTIF($B$2:$B45,B45)=1,1,0)) -> 0 | T45: =IF(S45=1,SUM($S$2:S45),"") | U45: =IF(W45="",0,IF(COUNTIF($W$2:$W45,W45)=1,1,0)) -> 1 | V45: =IF(U45=1,SUM($U$2:U45),"") -> 44 | W45: =IF(OR(C45="",B45=""),"",TRIM(C45)&"|"&TRIM(B45)) -> Zayed Al Rashdi|Emaar Properties
...

Sheet Auto populate sheets>>

Sheet Accounts Overview
A1: Account ID | B1: Account Name | C1: Sector | D1: Website | E1: Products/ Services | F1: Competitors | G1: Headquarters | H1: Primary Guradian | I1: Secondary PoC | J1: Engagements | K1: On Track | L1: For Review | M1: Overdue
A2: =IF(B2="","","ACC"&TEXT(ROW()-1,"0000")) -> ACC0001 | B2: =IFERROR(INDEX('Input Contact Information'!$B$2:$B$200,MATCH(ROW()-1,'Input Contact Information'!$T$2:$T$200,0)),"") -> QatarEnergy | C2: Energy | D2: https://www.qatarenergy.qa/ | E2: Oil & Gas | F2: Saudi Aramco; ExxonMobil; Shell; TotalEnergies; ADNOC | G2: Qatar, Middle East | H2: =IFERROR(INDEX('Input Contact Information'!$A$2:$A$200,MATCH($B2,'Input Contact Information'!$B$2:$B$200,0)),"") -> Wael Hatoum | I2: Alberto Michelotti | J2: =IF($B2="","",COUNTIFS('Input Contact Information'!$B$2:$B$200,$B2,'Input Contact Information'!$Q$2:$Q$200,"<>")) -> 3 | K2: =IF($B2="","",COUNTIFS('Contacts Overview'!$D$2:$D$200,$A2,'Contacts Overview'!$R$2:$R$200,"On Track")) -> 0 | L2: =IF($B2="","",COUNTIFS('Contacts Overview'!$D$2:$D$200,$A2,'Contacts Overview'!$R$2:$R$200,"For Review")) -> 0 | M2: =IF($B2="","",COUNTIFS('Contacts Overview'!$D$2:$D$200,$A2,'Contacts Overview'!$R$2:$R$200,"Overdue")) -> 3
A3: =IF(B3="","","ACC"&TEXT(ROW()-1,"0000")) -> ACC0002 | B3: =IFERROR(INDEX('Input Contact Information'!$B$2:$B$200,MATCH(ROW()-1,'Input Contact Information'!$T$2:$T$200,0)),"") -> Qatar Airways Group | C3: Transportation | D3: https://www.qatarairways.com | E3: Aviation | F3: Emirates; Etihad Airways; Turkish Airlines; Singapore Airlines; Cathay Pacific | G3: Qatar, Middle East | H3: =IFERROR(INDEX('Input Contact Information'!$A$2:$A$200,MATCH($B3,'Input Contact Information'!$B$2:$B$200,0)),"") -> Alberto Michelotti | I3: Eric Guraieb | J3: =IF($B3="","",COUNTIFS('Input Contact Information'!$B$2:$B$200,$B3,'Input Contact Information'!$Q$2:$Q$200,"<>")) -> 3 | K3: =IF($B3="","",COUNTIFS('Contacts Overview'!$D$2:$D$200,$A3,'Contacts Overview'!$R$2:$R$200,"On Track")) -> 1 | L3: =IF($B3="","",COUNTIFS('Contacts Overview'!$D$2:$D$200,$A3,'Contacts Overview'!$R$2:$R$200,"For Review")) -> 1 | M3: =IF($B3="","",COUNTIFS('Contacts Overview'!$D$2:$D$200,$A3,'Contacts Overview'!$R$2:$R$200,"Overdue")) -> 1
A4: =IF(B4="","","ACC"&TEXT(ROW()-1,"0000")) -> ACC0003 | B4: =IFERROR(INDEX('Input Contact Information'!$B$2:$B$200,MATCH(ROW()-1,'Input Contact Information'!$T$2:$T$200,0)),"") -> Qatar National Bank | C4: Financial Services | D4: https://www.qnb.com | E4: Banking | F4: Emirates NBD; First Abu Dhabi Bank; Qatar Islamic Bank; Commercial Bank of Qatar; Doha Bank | G4: Qatar, Middle East | H4: =IFERROR(INDEX('Input Contact Information'!$A$2:$A$200,MATCH($B4,'Input Contact Information'!$B$2:$B$200,0)),"") -> Eric Guraieb | I4: Kyle Strong | J4: =IF($B4="","",COUNTIFS('Input Contact Information'!$B$2:$B$200,$B4,'Input Contact Information'!$Q$2:$Q$200,"<>")) -> 3 | K4: =IF($B4="","",COUNTIFS('Contacts Overview'!$D$2:$D$200,$A4,'Contacts Overview'!$R$2:$R$200,"On Track")) -> 0 | L4: =IF($B4="","",COUNTIFS('Contacts Overview'!$D$2:$D$200,$A4,'Contacts Overview'!$R$2:$R$200,"For Review")) -> 0 | M4: =IF($B4="","",COUNTIFS('Contacts Overview'!$D$2:$D$200,$A4,'Contacts Overview'!$R$2:$R$200,"Overdue")) -> 3
A5: =IF(B5="","","ACC"&TEXT(ROW()-1,"0000")) -> ACC0004 | B5: =IFERROR(INDEX('Input Contact Information'!$B$2:$B$200,MATCH(ROW()-1,'Input Contact Information'!$T$2:$T$200,0)),"") -> Ooredoo Qatar | C5: Technology & Telecom | D5: https://www.ooredoo.qa | E5: Telecommunications | F5: Vodafone Qatar; stc (Saudi Telecom Company); e& (Etisalat); du (Emirates Integrated Telecom); Zain Group | G5: Qatar, Middle East | H5: =IFERROR(INDEX('Input Contact Information'!$A$2:$A$200,MATCH($B5,'Input Contact Information'!$B$2:$B$200,0)),"") -> Kyle Strong | I5: Sergey Glushkin | J5: =IF($B5="","",COUNTIFS('Input Contact Information'!$B$2:$B$200,$B5,'Input Contact Information'!$Q$2:$Q$200,"<>")) -> 3 | K5: =IF($B5="","",COUNTIFS('Contacts Overview'!$D$2:$D$200,$A5,'Contacts Overview'!$R$2:$R$200,"On Track")) -> 0 | L5: =IF($B5="","",COUNTIFS('Contacts Overview'!$D$2:$D$200,$A5,'Contacts Overview'!$R$2:$R$200,"For Review")) -> 0 | M5: =IF($B5="","",COUNTIFS('Contacts Overview'!$D$2:$D$200,$A5,'Contacts Overview'!$R$2:$R$200,"Overdue")) -> 3
A6: =IF(B6="","","ACC"&TEXT(ROW()-1,"0000")) -> ACC0005 | B6: =IFERROR(INDEX('Input Contact Information'!$B$2:$B$200,MATCH(ROW()-1,'Input Contact Information'!$T$2:$T$200,0)),"") -> Industries Qatar | C6: Industrials | D6: https://iq.com.qa/ | E6: Petrochemicals & Manufacturing | F6: SABIC; Yara International; OCI N.V.; ADNOC (Borouge); Ma'aden | G6: Qatar, Middle East | H6: =IFERROR(INDEX('Input Contact Information'!$A$2:$A$200,MATCH($B6,'Input Contact Information'!$B$2:$B$200,0)),"") -> Sergey Glushkin | I6: Naveed Vakil | J6: =IF($B6="","",COUNTIFS('Input Contact Information'!$B$2:$B$200,$B6,'Input Contact Information'!$Q$2:$Q$200,"<>")) -> 3 | K6: =IF($B6="","",COUNTIFS('Contacts Overview'!$D$2:$D$200,$A6,'Contacts Overview'!$R$2:$R$200,"On Track")) -> 0 | L6: =IF($B6="","",COUNTIFS('Contacts Overview'!$D$2:$D$200,$A6,'Contacts Overview'!$R$2:$R$200,"For Review")) -> 1 | M6: =IF($B6="","",COUNTIFS('Contacts Overview'!$D$2:$D$200,$A6,'Contacts Overview'!$R$2:$R$200,"Overdue")) -> 2
A7: =IF(B7="","","ACC"&TEXT(ROW()-1,"0000")) -> ACC0006 | B7: =IFERROR(INDEX('Input Contact Information'!$B$2:$B$200,MATCH(ROW()-1,'Input Contact Information'!$T$2:$T$200,0)),"") -> Commercial Bank of Qatar | C7: Financial Services | D7: https://www.cbq.qa | E7: Banking | F7: QNB; Doha Bank; Qatar Islamic Bank; Qatar International Islamic Bank; Ahli Bank Qatar | G7: Qatar, Middle East | H7: =IFERROR(INDEX('Input Contact Information'!$A$2:$A$200,MATCH($B7,'Input Contact Information'!$B$2:$B$200,0)),"") -> Alberto Michelotti | I7: Reda Jennane | J7: =IF($B7="","",COUNTIFS('Input Contact Information'!$B$2:$B$200,$B7,'Input Contact Information'!$Q$2:$Q$200,"<>")) -> 3 | K7: =IF($B7="","",COUNTIFS('Contacts Overview'!$D$2:$D$200,$A7,'Contacts Overview'!$R$2:$R$200,"On Track")) -> 0 | L7: =IF($B7="","",COUNTIFS('Contacts Overview'!$D$2:$D$200,$A7,'Contacts Overview'!$R$2:$R$200,"For Review")) -> 1 | M7: =IF($B7="","",COUNTIFS('Contacts Overview'!$D$2:$D$200,$A7,'Contacts Overview'!$R$2:$R$200,"Overdue")) -> 2
A8: =IF(B8="","","ACC"&TEXT(ROW()-1,"0000")) -> ACC0007 | B8: =IFERROR(INDEX('Input Contact Information'!$B$2:$B$200,MATCH(ROW()-1,'Input Contact Information'!$T$2:$T$200,0)),"") -> Doha Bank | C8: Financial Services | D8: https://qa.dohabank.com/ | E8: Banking | F8: QNB; Commercial Bank of Qatar; Qatar Islamic Bank; Ahli Bank Qatar; Al Khalij Commercial Bank | G8: Qatar, Middle East | H8: =IFERROR(INDEX('Input Contact Information'!$A$2:$A$200,MATCH($B8,'Input Contact Information'!$B$2:$B$200,0)),"") -> Eric Guraieb | I8: Riccardo Terruzzi | J8: =IF($B8="","",COUNTIFS('Input Contact Information'!$B$2:$B$200,$B8,'Input Contact Information'!$Q$2:$Q$200,"<>")) -> 3 | K8: =IF($B8="","",COUNTIFS('Contacts Overview'!$D$2:$D$200,$A8,'Contacts Overview'!$R$2:$R$200,"On Track")) -> 0 | L8: =IF($B8="","",COUNTIFS('Contacts Overview'!$D$2:$D$200,$A8,'Contacts Overview'!$R$2:$R$200,"For Review")) -> 1 | M8: =IF($B8="","",COUNTIFS('Contacts Overview'!$D$2:$D$200,$A8,'Contacts Overview'!$R$2:$R$200,"Overdue")) -> 2
A9: =IF(B9="","","ACC"&TEXT(ROW()-1,"0000")) -> ACC0008 | B9: =IFERROR(INDEX('Input Contact Information'!$B$2:$B$200,MATCH(ROW()-1,'Input Contact Information'!$T$2:$T$200,0)),"") -> Qatar Insurance Company | C9: Financial Services | D9: https://qic-group.com/ | E9: Insurance | F9: Gulf Insurance Group; Doha Insurance Group; Qatar General Insurance & Reinsurance; Al Khaleej Takaful Insurance; Sukoon (Oman Insurance Company) | G9: Qatar, Middle East | H9: =IFERROR(INDEX('Input Contact Information'!$A$2:$A$200,MATCH($B9,'Input Contact Information'!$B$2:$B$200,0)),"") -> Kyle Strong | I9: Stanislav Gaiduk | J9: =IF($B9="","",COUNTIFS('Input Contact Information'!$B$2:$B$200,$B9,'Input Contact Information'!$Q$2:$Q$200,"<>")) -> 3 | K9: =IF($B9="","",COUNTIFS('Contacts Overview'!$D$2:$D$200,$A9,'Contacts Overview'!$R$2:$R$200,"On Track")) -> 0 | L9: =IF($B9="","",COUNTIFS('Contacts Overview'!$D$2:$D$200,$A9,'Contacts Overview'!$R$2:$R$200,"For Review")) -> 3 | M9: =IF($B9="","",COUNTIFS('Contacts Overview'!$D$2:$D$200,$A9,'Contacts Overview'!$R$2:$R$200,"Overdue")) -> 0
A10: =IF(B10="","","ACC"&TEXT(ROW()-1,"0000")) -> ACC0009 | B10: =IFERROR(INDEX('Input Contact Information'!$B$2:$B$200,MATCH(ROW()-1,'Input Contact Information'!$T$2:$T$200,0)),"") -> Nakilat | C10: Transportation | D10: https://www.nakilat.com.qa | E10: Maritime & Logistics | F10: Mitsui O.S.K. Lines (MOL); NYK Line; GasLog; Teekay LNG Partners; MISC Berhad | G10: Qatar, Middle East | H10: =IFERROR(INDEX('Input Contact Information'!$A$2:$A$200,MATCH($B10,'Input Contact Information'!$B$2:$B$200,0)),"") -> Sergey Glushkin | I10: Badaoui Saroufim | J10: =IF($B10="","",COUNTIFS('Input Contact Information'!$B$2:$B$200,$B10,'Input Contact Information'!$Q$2:$Q$200,"<>")) -> 2 | K10: =IF($B10="","",COUNTIFS('Contacts Overview'!$D$2:$D$200,$A10,'Contacts Overview'!$R$2:$R$200,"On Track")) -> 0 | L10: =IF($B10="","",COUNTIFS('Contacts Overview'!$D$2:$D$200,$A10,'Contacts Overview'!$R$2:$R$200,"For Review")) -> 1 | M10: =IF($B10="","",COUNTIFS('Contacts Overview'!$D$2:$D$200,$A10,'Contacts Overview'!$R$2:$R$200,"Overdue")) -> 1
A11: =IF(B11="","","ACC"&TEXT(ROW()-1,"0000")) -> ACC0010 | B11: =IFERROR(INDEX('Input Contact Information'!$B$2:$B$200,MATCH(ROW()-1,'Input Contact Information'!$T$2:$T$200,0)),"") -> United Development Company | C11: Real Estate | D11: https://www.udcqatar.com | E11: Property Development | F11: Ezdan Holding Group; Barwa Real Estate Group; Qatari Diar; Msheireb Properties; Al Faisal Holding | G11: Qatar, Middle East | H11: =IFERROR(INDEX('Input Contact Information'!$A$2:$A$200,MATCH($B11,'Input Contact Information'!$B$2:$B$200,0)),"") -> Naveed Vakil | I11: Meher Ben Marzouk | J11: =IF($B11="","",COUNTIFS('Input Contact Information'!$B$2:$B$200,$B11,'Input Contact Information'!$Q$2:$Q$200,"<>")) -> 3 | K11: =IF($B11="","",COUNTIFS('Contacts Overview'!$D$2:$D$200,$A11,'Contacts Overview'!$R$2:$R$200,"On Track")) -> 0 | L11: =IF($B11="","",COUNTIFS('Contacts Overview'!$D$2:$D$200,$A11,'Contacts Overview'!$R$2:$R$200,"For Review")) -> 1 | M11: =IF($B11="","",COUNTIFS('Contacts Overview'!$D$2:$D$200,$A11,'Contacts Overview'!$R$2:$R$200,"Overdue")) -> 2
A12: =IF(B12="","","ACC"&TEXT(ROW()-1,"0000")) -> ACC0011 | B12: =IFERROR(INDEX('Input Contact Information'!$B$2:$B$200,MATCH(ROW()-1,'Input Contact Information'!$T$2:$T$200,0)),"") -> Milaha | C12: Transportation | D12: https://www.milaha.com/ | E12: Maritime & Logistics | F12: AD Ports Group; GAC Group; Gulf Warehousing Company (GWC); Bahri (National Shipping Company of Saudi Arabia); NYK Line | G12: Qatar, Middle East | H12: =IFERROR(INDEX('Input Contact Information'!$A$2:$A$200,MATCH($B12,'Input Contact Information'!$B$2:$B$200,0)),"") -> Reda Jennane | I12: Sidhant Shetty | J12: =IF($B12="","",COUNTIFS('Input Contact Information'!$B$2:$B$200,$B12,'Input Contact Information'!$Q$2:$Q$200,"<>")) -> 3 | K12: =IF($B12="","",COUNTIFS('Contacts Overview'!$D$2:$D$200,$A12,'Contacts Overview'!$R$2:$R$200,"On Track")) -> 1 | L12: =IF($B12="","",COUNTIFS('Contacts Overview'!$D$2:$D$200,$A12,'Contacts Overview'!$R$2:$R$200,"For Review")) -> 1 | M12: =IF($B12="","",COUNTIFS('Contacts Overview'!$D$2:$D$200,$A12,'Contacts Overview'!$R$2:$R$200,"Overdue")) -> 1
A13: =IF(B13="","","ACC"&TEXT(ROW()-1,"0000")) -> ACC0012 | B13: =IFERROR(INDEX('Input Contact Information'!$B$2:$B$200,MATCH(ROW()-1,'Input Contact Information'!$T$2:$T$200,0)),"") -> Baladna | C13: Consumer Goods | D13: https://www.baladna.com | E13: Food & Beverage | F13: Almarai; NADEC (National Agricultural Development Company); Al Rawabi Dairy; Arla Foods; SADAFCO | G13: Qatar, Middle East | H13: =IFERROR(INDEX('Input Contact Information'!$A$2:$A$200,MATCH($B13,'Input Contact Information'!$B$2:$B$200,0)),"") -> Riccardo Terruzzi | I13: Shantanu Mittal | J13: =IF($B13="","",COUNTIFS('Input Contact Information'!$B$2:$B$200,$B13,'Input Contact Information'!$Q$2:$Q$200,"<>")) -> 3 | K13: =IF($B13="","",COUNTIFS('Contacts Overview'!$D$2:$D$200,$A13,'Contacts Overview'!$R$2:$R$200,"On Track")) -> 1 | L13: =IF($B13="","",COUNTIFS('Contacts Overview'!$D$2:$D$200,$A13,'Contacts Overview'!$R$2:$R$200,"For Review")) -> 1 | M13: =IF($B13="","",COUNTIFS('Contacts Overview'!$D$2:$D$200,$A13,'Contacts Overview'!$R$2:$R$200,"Overdue")) -> 1
... A17: =IF(B17="","","ACC"&TEXT(ROW()-1,"0000")) -> ACC0016 | B17: =IFERROR(INDEX('Input Contact Information'!$B$2:$B$200,MATCH(ROW()-1,'Input Contact Information'!$T$2:$T$200,0)),"") -> Invest Qatar | C17: Government & Public Sector | D17: https://www.invest.qa | E17: Investment promotion agency | F17: Dubai FDI (Dubai Investment Development Agency); Abu Dhabi Investment Office (ADIO); Invest Saudi (MISA); Bahrain EDB; Kuwait Direct Investment Promotion Authority (KDIPA) | G17: Qatar, Middle East | H17: =IFERROR(INDEX('Input Contact Information'!$A$2:$A$200,MATCH($B17,'Input Contact Information'!$B$2:$B$200,0)),"") -> Eric Guraieb | I17: Naveed Vakil | J17: =IF($B17="","",COUNTIFS('Input Contact Information'!$B$2:$B$200,$B17,'Input Contact Information'!$Q$2:$Q$200,"<>")) -> 0 | K17: =IF($B17="","",COUNTIFS('Contacts Overview'!$D$2:$D$200,$A17,'Contacts Overview'!$R$2:$R$200,"On Track")) -> 0 | L17: =IF($B17="","",COUNTIFS('Contacts Overview'!$D$2:$D$200,$A17,'Contacts Overview'!$R$2:$R$200,"For Review")) -> 0 | M17: =IF($B17="","",COUNTIFS('Contacts Overview'!$D$2:$D$200,$A17,'Contacts Overview'!$R$2:$R$200,"Overdue")) -> 0
A18: =IF(B18="","","ACC"&TEXT(ROW()-1,"0000")) | B18: =IFERROR(INDEX('Input Contact Information'!$B$2:$B$200,MATCH(ROW()-1,'Input Contact Information'!$T$2:$T$200,0)),"") | H18: =IFERROR(INDEX('Input Contact Information'!$A$2:$A$200,MATCH($B18,'Input Contact Information'!$B$2:$B$200,0)),"") | J18: =IF($B18="","",COUNTIFS('Input Contact Information'!$B$2:$B$200,$B18,'Input Contact Information'!$Q$2:$Q$200,"<>")) | K18: =IF($B18="","",COUNTIFS('Contacts Overview'!$D$2:$D$200,$A18,'Contacts Overview'!$R$2:$R$200,"On Track")) | L18: =IF($B18="","",COUNTIFS('Contacts Overview'!$D$2:$D$200,$A18,'Contacts Overview'!$R$2:$R$200,"For Review")) | M18: =IF($B18="","",COUNTIFS('Contacts Overview'!$D$2:$D$200,$A18,'Contacts Overview'!$R$2:$R$200,"Overdue"))
A19: =IF(B19="","","ACC"&TEXT(ROW()-1,"0000")) | B19: =IFERROR(INDEX('Input Contact Information'!$B$2:$B$200,MATCH(ROW()-1,'Input Contact Information'!$T$2:$T$200,0)),"") | H19: =IFERROR(INDEX('Input Contact Information'!$A$2:$A$200,MATCH($B19,'Input Contact Information'!$B$2:$B$200,0)),"") | J19: =IF($B19="","",COUNTIFS('Input Contact Information'!$B$2:$B$200,$B19,'Input Contact Information'!$Q$2:$Q$200,"<>")) | K19: =IF($B19="","",COUNTIFS('Contacts Overview'!$D$2:$D$200,$A19,'Contacts Overview'!$R$2:$R$200,"On Track")) | L19: =IF($B19="","",COUNTIFS('Contacts Overview'!$D$2:$D$200,$A19,'Contacts Overview'!$R$2:$R$200,"For Review")) | M19: =IF($B19="","",COUNTIFS('Contacts Overview'!$D$2:$D$200,$A19,'Contacts Overview'!$R$2:$R$200,"Overdue"))
A20: =IF(B20="","","ACC"&TEXT(ROW()-1,"0000")) | B20: =IFERROR(INDEX('Input Contact Information'!$B$2:$B$200,MATCH(ROW()-1,'Input Contact Information'!$T$2:$T$200,0)),"") | H20: =IFERROR(INDEX('Input Contact Information'!$A$2:$A$200,MATCH($B20,'Input Contact Information'!$B$2:$B$200,0)),"") | J20: =IF($B20="","",COUNTIFS('Input Contact Information'!$B$2:$B$200,$B20,'Input Contact Information'!$Q$2:$Q$200,"<>")) | K20: =IF($B20="","",COUNTIFS('Contacts Overview'!$D$2:$D$200,$A20,'Contacts Overview'!$R$2:$R$200,"On Track")) | L20: =IF($B20="","",COUNTIFS('Contacts Overview'!$D$2:$D$200,$A20,'Contacts Overview'!$R$2:$R$200,"For Review")) | M20: =IF($B20="","",COUNTIFS('Contacts Overview'!$D$2:$D$200,$A20,'Contacts Overview'!$R$2:$R$200,"Overdue"))
A21: =IF(B21="","","ACC"&TEXT(ROW()-1,"0000")) | B21: =IFERROR(INDEX('Input Contact Information'!$B$2:$B$200,MATCH(ROW()-1,'Input Contact Information'!$T$2:$T$200,0)),"") | H21: =IFERROR(INDEX('Input Contact Information'!$A$2:$A$200,MATCH($B21,'Input Contact Information'!$B$2:$B$200,0)),"") | J21: =IF($B21="","",COUNTIFS('Input Contact Information'!$B$2:$B$200,$B21,'Input Contact Information'!$Q$2:$Q$200,"<>")) | K21: =IF($B21="","",COUNTIFS('Contacts Overview'!$D$2:$D$200,$A21,'Contacts Overview'!$R$2:$R$200,"On Track")) | L21: =IF($B21="","",COUNTIFS('Contacts Overview'!$D$2:$D$200,$A21,'Contacts Overview'!$R$2:$R$200,"For Review")) | M21: =IF($B21="","",COUNTIFS('Contacts Overview'!$D$2:$D$200,$A21,'Contacts Overview'!$R$2:$R$200,"Overdue"))
A22: =IF(B22="","","ACC"&TEXT(ROW()-1,"0000")) | B22: =IFERROR(INDEX('Input Contact Information'!$B$2:$B$200,MATCH(ROW()-1,'Input Contact Information'!$T$2:$T$200,0)),"") | H22: =IFERROR(INDEX('Input Contact Information'!$A$2:$A$200,MATCH($B22,'Input Contact Information'!$B$2:$B$200,0)),"") | J22: =IF($B22="","",COUNTIFS('Input Contact Information'!$B$2:$B$200,$B22,'Input Contact Information'!$Q$2:$Q$200,"<>")) | K22: =IF($B22="","",COUNTIFS('Contacts Overview'!$D$2:$D$200,$A22,'Contacts Overview'!$R$2:$R$200,"On Track")) | L22: =IF($B22="","",COUNTIFS('Contacts Overview'!$D$2:$D$200,$A22,'Contacts Overview'!$R$2:$R$200,"For Review")) | M22: =IF($B22="","",COUNTIFS('Contacts Overview'!$D$2:$D$200,$A22,'Contacts Overview'!$R$2:$R$200,"Overdue"))
A23: =IF(B23="","","ACC"&TEXT(ROW()-1,"0000")) | B23: =IFERROR(INDEX('Input Contact Information'!$B$2:$B$200,MATCH(ROW()-1,'Input Contact Information'!$T$2:$T$200,0)),"") | H23: =IFERROR(INDEX('Input Contact Information'!$A$2:$A$200,MATCH($B23,'Input Contact Information'!$B$2:$B$200,0)),"") | J23: =IF($B23="","",COUNTIFS('Input Contact Information'!$B$2:$B$200,$B23,'Input Contact Information'!$Q$2:$Q$200,"<>")) | K23: =IF($B23="","",COUNTIFS('Contacts Overview'!$D$2:$D$200,$A23,'Contacts Overview'!$R$2:$R$200,"On Track")) | L23: =IF($B23="","",COUNTIFS('Contacts Overview'!$D$2:$D$200,$A23,'Contacts Overview'!$R$2:$R$200,"For Review")) | M23: =IF($B23="","",COUNTIFS('Contacts Overview'!$D$2:$D$200,$A23,'Contacts Overview'!$R$2:$R$200,"Overdue"))
A24: =IF(B24="","","ACC"&TEXT(ROW()-1,"0000")) | B24: =IFERROR(INDEX('Input Contact Information'!$B$2:$B$200,MATCH(ROW()-1,'Input Contact Information'!$T$2:$T$200,0)),"") | H24: =IFERROR(INDEX('Input Contact Information'!$A$2:$A$200,MATCH($B24,'Input Contact Information'!$B$2:$B$200,0)),"") | J24: =IF($B24="","",COUNTIFS('Input Contact Information'!$B$2:$B$200,$B24,'Input Contact Information'!$Q$2:$Q$200,"<>")) | K24: =IF($B24="","",COUNTIFS('Contacts Overview'!$D$2:$D$200,$A24,'Contacts Overview'!$R$2:$R$200,"On Track")) | L24: =IF($B24="","",COUNTIFS('Contacts Overview'!$D$2:$D$200,$A24,'Contacts Overview'!$R$2:$R$200,"For Review")) | M24: =IF($B24="","",COUNTIFS('Contacts Overview'!$D$2:$D$200,$A24,'Contacts Overview'!$R$2:$R$200,"Overdue"))
